2023-06-22 08:36:06,579 ERROR scheduler Exception in Enqueue Events for Site dem
Traceback (most recent call last):
  File "/workspaces/frappe_dock/frappe/frappe-bench/env/lib/python3.10/site-packages/pymysql/connections.py", line 616, in connect
    sock = socket.create_connection(
  File "/home/frappe/.pyenv/versions/3.10.5/lib/python3.10/socket.py", line 824, in create_connection
    for res in getaddrinfo(host, port, 0, SOCK_STREAM):
  File "/home/frappe/.pyenv/versions/3.10.5/lib/python3.10/socket.py", line 955, in getaddrinfo
    for res in _socket.getaddrinfo(host, port, family, type, proto, flags):
socket.gaierror: [Errno -2] Name or service not known

During handling of the above exception, another exception occurred:

Traceback (most recent call last):
  File "/workspaces/frappe_dock/frappe/frappe-bench/apps/frappe/frappe/utils/scheduler.py", line 69, in enqueue_events_for_site
    if is_scheduler_inactive():
  File "/workspaces/frappe_dock/frappe/frappe-bench/apps/frappe/frappe/utils/scheduler.py", line 106, in is_scheduler_inactive
    if is_scheduler_disabled(verbose=verbose):
  File "/workspaces/frappe_dock/frappe/frappe-bench/apps/frappe/frappe/utils/scheduler.py", line 119, in is_scheduler_disabled
    frappe.db.get_single_value("System Settings", "enable_scheduler")
  File "/workspaces/frappe_dock/frappe/frappe-bench/apps/frappe/frappe/database/database.py", line 788, in get_single_value
    ).run()
  File "/workspaces/frappe_dock/frappe/frappe-bench/apps/frappe/frappe/query_builder/utils.py", line 86, in execute_query
    result = frappe.db.sql(query, params, *args, **kwargs)  # nosemgrep
  File "/workspaces/frappe_dock/frappe/frappe-bench/apps/frappe/frappe/database/database.py", line 210, in sql
    self.connect()
  File "/workspaces/frappe_dock/frappe/frappe-bench/apps/frappe/frappe/database/database.py", line 125, in connect
    self._conn = self.get_connection()
  File "/workspaces/frappe_dock/frappe/frappe-bench/apps/frappe/frappe/database/mariadb/database.py", line 102, in get_connection
    conn = self._get_connection()
  File "/workspaces/frappe_dock/frappe/frappe-bench/apps/frappe/frappe/database/mariadb/database.py", line 108, in _get_connection
    return self.create_connection()
  File "/workspaces/frappe_dock/frappe/frappe-bench/apps/frappe/frappe/database/mariadb/database.py", line 111, in create_connection
    return pymysql.connect(**self.get_connection_settings())
  File "/workspaces/frappe_dock/frappe/frappe-bench/env/lib/python3.10/site-packages/pymysql/connections.py", line 352, in __init__
    self.connect()
  File "/workspaces/frappe_dock/frappe/frappe-bench/env/lib/python3.10/site-packages/pymysql/connections.py", line 668, in connect
    raise exc
pymysql.err.OperationalError: (2003, "Can't connect to MySQL server on 'mariadb' ([Errno -2] Name or service not known)")
